Workbook

Sheet Assumptions
A1: Model Assumptions
A2: Home field advantage (pts) | B2: 2.5 | C2: Added to home team rating; 0 at neutral sites. Source: user spec.
A3: Spread standard deviation | B3: 16 | C3: Sigma in NORMDIST. Source: Adjust cell B1, Wk_01_Sch, 2025_NCAA.xlsx.
A4: Default FCS rating | B4: -32.9 | C4: ASSUMPTION: FCS opponents are not in SP+. Defaulted to the worst FBS rating (UMass). Override any team on Ratings tab.
A5: SP+ ratings | C5: 2026 preseason SP+, as supplied in NCAA_2026.xlsx.
A6: Schedule source | C6: Weeks 0-13 as supplied. Weeks 0-13 as supplied, PLUS Army vs Navy (Dec 12 2026, MetLife Stadium, neutral site) added by Claude. Source: westpoint.edu, metlifestadium.com, CBS Sports.
A8: FCS CONFERENCE BASELINES (SP+ scale) | C8: ASSUMPTION: FCS teams have no SP+ rating. Calibrated against the two FCS->FBS transition programs in SP+: NDSU -1.8 and Sac State -23.4.
A9: MVFC | B9: -19
A10: Big Sky | B10: -23
A11: CAA | B11: -26
A12: SoCon | B12: -30
A13: UAC | B13: -33
A14: Southland | B14: -34
A15: BigSouth-OVC | B15: -34
A16: SWAC | B16: -37
A17: Patriot | B17: -39
A18: MEAC | B18: -39
A19: NEC | B19: -44
A21: PROGRAM TIER ADJUSTMENT (pts)
A22: Elite | B22: 8
A23: Strong | B23: 4
A24: Average | B24: 0
A25: Weak | B25: -5
A26: Transition | B26: -12
A28: LEGEND
A29: Blue text on yellow = input you can change
A30: Black text = calculated, do not overwrite
A31: FCS rating = conference baseline + program tier adjustment. Edit either table above,
A32: or type a number straight over any rating on the Ratings tab to override one team.

Sheet Win_Probabilities
A1: Rank | B1: Team | C1: Rating | D1: Gms | E1: Exp Wins | F1: P(0) | G1: P(1) | H1: P(2) | I1: P(3) | J1: P(4) | K1: P(5) | L1: P(6) | M1: P(7) | N1: P(8) | O1: P(9) | P1: P(10) | Q1: P(11) | R1: P(12) | S1: P(13) | T1: Most Likely | U1: P(6+) Bowl | V1: P(10+) | W1: Sum Check
A2: =RANK(E2,$E$2:$E$139) -> 3 | B2: Ohio St. | C2: =Schedule!$B$2 -> 32.7 | D2: 12 | E2: =Schedule!$BQ$2 -> 10.205967 | F2: =Convolution!O4 -> 1.4059449e-17 | G2: =Convolution!O5 -> 2.6127181e-13 | H2: =Convolution!O6 -> 1.1055997e-09 | I2: =Convolution!O7 -> 1.1994279e-07 | J2: =Convolution!O8 -> 5.227822e-06 | K2: =Convolution!O9 -> 0.00011850071 | L2: =Convolution!O10 -> 0.0015479489 | M2: =Convolution!O11 -> 0.012248321 | N2: =Convolution!O12 -> 0.059857848 | O2: =Convolution!O13 -> 0.1796222 | P2: =Convolution!O14 -> 0.31915999 | Q2: =Convolution!O15 -> 0.3060136 | R2: =Convolution!O16 -> 0.12142624 | S2: =Convolution!O17 -> 0 | T2: =INDEX($F$1:$S$1,MATCH(MAX(F2:S2),F2:S2,0)) -> P(10) | U2: =SUM(L2:S2) -> 0.99987615 | V2: =SUM(P2:S2) -> 0.74659984 | W2: =ROUND(SUM(F2:S2),6) -> 1
A3: =RANK(E3,$E$2:$E$139) -> 4 | B3: Oregon | C3: =Schedule!$B$3 -> 29.2 | D3: 12 | E3: =Schedule!$BQ$3 -> 10.175094 | F3: =Convolution!O20 -> 1.6456411e-14 | G3: =Convolution!O21 -> 5.4133622e-11 | H3: =Convolution!O22 -> 5.9119966e-09 | I3: =Convolution!O23 -> 2.8364805e-07 | J3: =Convolution!O24 -> 7.7755704e-06 | K3: =Convolution!O25 -> 0.00013427488 | L3: =Convolution!O26 -> 0.0015229126 | M3: =Convolution!O27 -> 0.011485801 | N3: =Convolution!O28 -> 0.057042737 | O3: =Convolution!O29 -> 0.18019772 | P3: =Convolution!O30 -> 0.33622829 | Q3: =Convolution!O31 -> 0.31611413 | R3: =Convolution!O32 -> 0.097266069 | S3: =Convolution!O33 -> 0 | T3: =INDEX($F$1:$S$1,MATCH(MAX(F3:S3),F3:S3,0)) -> P(10) | U3: =SUM(L3:S3) -> 0.99985766 | V3: =SUM(P3:S3) -> 0.74960849 | W3: =ROUND(SUM(F3:S3),6) -> 1
A4: =RANK(E4,$E$2:$E$139) -> 1 | B4: Notre Dame | C4: =Schedule!$B$4 -> 26.5 | D4: 12 | E4: =Schedule!$BQ$4 -> 10.800983 | F4: =Convolution!O36 -> 1.3297554e-15 | G4: =Convolution!O37 -> 7.1494442e-13 | H4: =Convolution!O38 -> 1.0555058e-10 | I4: =Convolution!O39 -> 7.6591734e-09 | J4: =Convolution!O40 -> 3.2741868e-07 | K4: =Convolution!O41 -> 8.9330565e-06 | L4: =Convolution!O42 -> 0.00016132702 | M4: =Convolution!O43 -> 0.0019485353 | N4: =Convolution!O44 -> 0.015572268 | O4: =Convolution!O45 -> 0.079651189 | P4: =Convolution!O46 -> 0.24440246 | Q4: =Convolution!O47 -> 0.39819323 | R4: =Convolution!O48 -> 0.26006172 | S4: =Convolution!O49 -> 0 | T4: =INDEX($F$1:$S$1,MATCH(MAX(F4:S4),F4:S4,0)) -> P(11) | U4: =SUM(L4:S4) -> 0.99999073 | V4: =SUM(P4:S4) -> 0.90265741 | W4: =ROUND(SUM(F4:S4),6) -> 1
A5: =RANK(E5,$E$2:$E$139) -> 7 | B5: Georgia | C5: =Schedule!$B$5 -> 26.4 | D5: 12 | E5: =Schedule!$BQ$5 -> 9.9177097 | F5: =Convolution!O52 -> 2.6126586e-14 | G5: =Convolution!O53 -> 6.2180656e-10 | H5: =Convolution!O54 -> 8.2757282e-08 | I5: =Convolution!O55 -> 3.2593984e-06 | J5: =Convolution!O56 -> 6.4130211e-05 | K5: =Convolution!O57 -> 0.00075030107 | L5: =Convolution!O58 -> 0.0056465059 | M5: =Convolution!O59 -> 0.028343097 | N5: =Convolution!O60 -> 0.095852831 | O5: =Convolution!O61 -> 0.2155307 | P5: =Convolution!O62 -> 0.30847667 | Q5: =Convolution!O63 -> 0.25394369 | R5: =Convolution!O64 -> 0.091388724 | S5: =Convolution!O65 -> 0 | T5: =INDEX($F$1:$S$1,MATCH(MAX(F5:S5),F5:S5,0)) -> P(10) | U5: =SUM(L5:S5) -> 0.99918223 | V5: =SUM(P5:S5) -> 0.65380909 | W5: =ROUND(SUM(F5:S5),6) -> 1
A6: =RANK(E6,$E$2:$E$139) -> 5 | B6: Indiana | C6: =Schedule!$B$6 -> 25.8 | D6: 12 | E6: =Schedule!$BQ$6 -> 9.9767659 | F6: =Convolution!O68 -> 6.0183259e-17 | G6: =Convolution!O69 -> 4.6545479e-12 | H6: =Convolution!O70 -> 1.4471076e-09 | I6: =Convolution!O71 -> 1.511179e-07 | J6: =Convolution!O72 -> 7.0144064e-06 | K6: =Convolution!O73 -> 0.00016647426 | L6: =Convolution!O74 -> 0.0022148291 | M6: =Convolution!O75 -> 0.017284864 | N6: =Convolution!O76 -> 0.080222285 | O6: =Convolution!O77 -> 0.21942498 | P6: =Convolution!O78 -> 0.33906346 | Q6: =Convolution!O79 -> 0.26500705 | R6: =Convolution!O80 -> 0.076608892 | S6: =Convolution!O81 -> 0 | T6: =INDEX($F$1:$S$1,MATCH(MAX(F6:S6),F6:S6,0)) -> P(10) | U6: =SUM(L6:S6) -> 0.99982636 | V6: =SUM(P6:S6) -> 0.6806794 | W6: =ROUND(SUM(F6:S6),6) -> 1
A7: =RANK(E7,$E$2:$E$139) -> 18 | B7: Texas | C7: =Schedule!$B$7 -> 22.8 | D7: 12 | E7: =Schedule!$BQ$7 -> 8.2406365 | F7: =Convolution!O84 -> 2.0501319e-08 | G7: =Convolution!O85 -> 1.4457163e-06 | H7: =Convolution!O86 -> 4.046756e-05 | I7: =Convolution!O87 -> 0.0005879318 | J7: =Convolution!O88 -> 0.0049405675 | K7: =Convolution!O89 -> 0.025504794 | L7: =Convolution!O90 -> 0.084341563 | M7: =Convolution!O91 -> 0.18307932 | N7: =Convolution!O92 -> 0.26247453 | O7: =Convolution!O93 -> 0.24480995 | P7: =Convolution!O94 -> 0.14190135 | Q7: =Convolution!O95 -> 0.04601657 | R7: =Convolution!O96 -> 0.0063014866 | S7: =Convolution!O97 -> 0 | T7: =INDEX($F$1:$S$1,MATCH(MAX(F7:S7),F7:S7,0)) -> P(8) | U7: =SUM(L7:S7) -> 0.96892477 | V7: =SUM(P7:S7) -> 0.19421941 | W7: =ROUND(SUM(F7:S7),6) -> 1
A8: =RANK(E8,$E$2:$E$139) -> 6 | B8: Miami | C8: =Schedule!$B$8 -> 22 | D8: 12 | E8: =Schedule!$BQ$8 -> 9.9583102 | F8: =Convolution!O100 -> 3.7063826e-15 | G8: =Convolution!O101 -> 6.1982089e-11 | H8: =Convolution!O102 -> 1.3388775e-08 | I8: =Convolution!O103 -> 7.5307337e-07 | J8: =Convolution!O104 -> 2.0242066e-05 | K8: =Convolution!O105 -> 0.00031494091 | L8: =Convolution!O106 -> 0.0030829313 | M8: =Convolution!O107 -> 0.019656513 | N8: =Convolution!O108 -> 0.081854401 | O8: =Convolution!O109 -> 0.21648552 | P8: =Convolution!O110 -> 0.33871396 | Q8: =Convolution!O111 -> 0.26823414 | R8: =Convolution!O112 -> 0.071636591 | S8: =Convolution!O113 -> 0 | T8: =INDEX($F$1:$S$1,MATCH(MAX(F8:S8),F8:S8,0)) -> P(10) | U8: =SUM(L8:S8) -> 0.99966405 | V8: =SUM(P8:S8) -> 0.67858469 | W8: =ROUND(SUM(F8:S8),6) -> 1
A9: =RANK(E9,$E$2:$E$139) -> 2 | B9: Texas Tech | C9: =Schedule!$B$9 -> 21.8 | D9: 12 | E9: =Schedule!$BQ$9 -> 10.610496 | F9: =Convolution!O116 -> 4.1616043e-16 | G9: =Convolution!O117 -> 1.4930203e-12 | H9: =Convolution!O118 -> 1.2668126e-09 | I9: =Convolution!O119 -> 9.2865174e-08 | J9: =Convolution!O120 -> 3.0499312e-06 | K9: =Convolution!O121 -> 5.7776053e-05 | L9: =Convolution!O122 -> 0.0006980382 | M9: =Convolution!O123 -> 0.0056301297 | N9: =Convolution!O124 -> 0.030771155 | O9: =Convolution!O125 -> 0.11276836 | P9: =Convolution!O126 -> 0.26569 | Q9: =Convolution!O127 -> 0.36396611 | R9: =Convolution!O128 -> 0.2204153 | S9: =Convolution!O129 -> 0 | T9: =INDEX($F$1:$S$1,MATCH(MAX(F9:S9),F9:S9,0)) -> P(11) | U9: =SUM(L9:S9) -> 0.99993908 | V9: =SUM(P9:S9) -> 0.8500714 | W9: =ROUND(SUM(F9:S9),6) -> 1
A10: =RANK(E10,$E$2:$E$139) -> 15 | B10: Texas A&M | C10: =Schedule!$B$10 -> 20.9 | D10: 12 | E10: =Schedule!$BQ$10 -> 8.4507633 | F10: =Convolution!O132 -> 1.2285681e-11 | G10: =Convolution!O133 -> 3.2511856e-08 | H10: =Convolution!O134 -> 8.2726829e-06 | I10: =Convolution!O135 -> 0.00022634997 | J10: =Convolution!O136 -> 0.0026719145 | K10: =Convolution!O137 -> 0.017197167 | L10: =Convolution!O138 -> 0.066390744 | M10: =Convolution!O139 -> 0.16197632 | N10: =Convolution!O140 -> 0.25579275 | O10: =Convolution!O141 -> 0.26085947 | P10: =Convolution!O142 -> 0.1658224 | Q10: =Convolution!O143 -> 0.059740654 | R10: =Convolution!O144 -> 0.0093139206 | S10: =Convolution!O145 -> 0 | T10: =INDEX($F$1:$S$1,MATCH(MAX(F10:S10),F10:S10,0)) -> P(9) | U10: =SUM(L10:S10) -> 0.97989626 | V10: =SUM(P10:S10) -> 0.23487698 | W10: =ROUND(SUM(F10:S10),6) -> 1
A11: =RANK(E11,$E$2:$E$139) -> 13 | B11: LSU | C11: =Schedule!$B$11 -> 20.4 | D11: 12 | E11: =Schedule!$BQ$11 -> 8.5305373 | F11: =Convolution!O148 -> 4.5389173e-11 | G11: =Convolution!O149 -> 2.4433805e-07 | H11: =Convolution!O150 -> 1.6384515e-05 | I11: =Convolution!O151 -> 0.00031935872 | J11: =Convolution!O152 -> 0.0030704536 | K11: =Convolution!O153 -> 0.017395004 | L11: =Convolution!O154 -> 0.062968322 | M11: =Convolution!O155 -> 0.15129862 | N11: =Convolution!O156 -> 0.24410136 | O11: =Convolution!O157 -> 0.26130506 | P11: =Convolution!O158 -> 0.17789397 | Q11: =Convolution!O159 -> 0.06968171 | R11: =Convolution!O160 -> 0.011949512 | S11: =Convolution!O161 -> 0 | T11: =INDEX($F$1:$S$1,MATCH(MAX(F11:S11),F11:S11,0)) -> P(9) | U11: =SUM(L11:S11) -> 0.97919856 | V11: =SUM(P11:S11) -> 0.25952519 | W11: =ROUND(SUM(F11:S11),6) -> 1
A12: =RANK(E12,$E$2:$E$139) -> 42 | B12: Oklahoma | C12: =Schedule!$B$12 -> 18.8 | D12: 12 | E12: =Schedule!$BQ$12 -> 7.5417647 | F12: =Convolution!O164 -> 5.3605852e-08 | G12: =Convolution!O165 -> 1.1037162e-05 | H12: =Convolution!O166 -> 0.00028168061 | I12: =Convolution!O167 -> 0.003057759 | J12: =Convolution!O168 -> 0.018167477 | K12: =Convolution!O169 -> 0.06594615 | L12: =Convolution!O170 -> 0.15474901 | M12: =Convolution!O171 -> 0.24124997 | N12: =Convolution!O172 -> 0.25125537 | O12: =Convolution!O173 -> 0.17193418 | P12: =Convolution!O174 -> 0.073722452 | Q12: =Convolution!O175 -> 0.017800903 | R12: =Convolution!O176 -> 0.0018239549 | S12: =Convolution!O177 -> 0 | T12: =INDEX($F$1:$S$1,MATCH(MAX(F12:S12),F12:S12,0)) -> P(8) | U12: =SUM(L12:S12) -> 0.91253584 | V12: =SUM(P12:S12) -> 0.09334731 | W12: =ROUND(SUM(F12:S12),6) -> 1
A13: =RANK(E13,$E$2:$E$139) -> 31 | B13: USC | C13: =Schedule!$B$13 -> 17.7 | D13: 12 | E13: =Schedule!$BQ$13 -> 7.8136586 | F13: =Convolution!O180 -> 6.2168745e-09 | G13: =Convolution!O181 -> 8.9142423e-07 | H13: =Convolution!O182 -> 3.9762349e-05 | I13: =Convolution!O183 -> 0.00073137502 | J13: =Convolution!O184 -> 0.0068642851 | K13: =Convolution!O185 -> 0.036848259 | L13: =Convolution!O186 -> 0.11944892 | M13: =Convolution!O187 -> 0.23790613 | N13: =Convolution!O188 -> 0.28857917 | O13: =Convolution!O189 -> 0.20707287 | P13: =Convolution!O190 -> 0.083671316 | Q13: =Convolution!O191 -> 0.017397344 | R13: =Convolution!O192 -> 0.0014396731 | S13: =Convolution!O193 -> 0 | T13: =INDEX($F$1:$S$1,MATCH(MAX(F13:S13),F13:S13,0)) -> P(8) | U13: =SUM(L13:S13) -> 0.95551542 | V13: =SUM(P13:S13) -> 0.10250833 | W13: =ROUND(SUM(F13:S13),6) -> 1
A14: =RANK(E14,$E$2:$E$139) -> 32 | B14: Alabama | C14: =Schedule!$B$14 -> 17.6 | D14: 12 | E14: =Schedule!$BQ$14 -> 7.8006462 | F14: =Convolution!O196 -> 1.1361072e-08 | G14: =Convolution!O197 -> 6.0555584e-06 | H14: =Convolution!O198 -> 0.00017037385 | I14: =Convolution!O199 -> 0.0019605654 | J14: =Convolution!O200 -> 0.012453846 | K14: =Convolution!O201 -> 0.049170819 | L14: =Convolution!O202 -> 0.12749528 | M14: =Convolution!O203 -> 0.22206135 | N14: =Convolution!O204 -> 0.25991623 | O14: =Convolution!O205 -> 0.20032546 | P14: =Convolution!O206 -> 0.096858475 | Q14: =Convolution!O207 -> 0.02647513 | R14: =Convolution!O208 -> 0.0031064137 | S14: =Convolution!O209 -> 0 | T14: =INDEX($F$1:$S$1,MATCH(MAX(F14:S14),F14:S14,0)) -> P(8) | U14: =SUM(L14:S14) -> 0.93623833 | V14: =SUM(P14:S14) -> 0.12644002 | W14: =ROUND(SUM(F14:S14),6) -> 1
A15: =RANK(E15,$E$2:$E$139) -> 28 | B15: Tennessee | C15: =Schedule!$B$15 -> 17.3 | D15: 12 | E15: =Schedule!$BQ$15 -> 7.9172438 | F15: =Convolution!O212 -> 2.7555422e-09 | G15: =Convolution!O213 -> 1.4903359e-06 | H15: =Convolution!O214 -> 8.9167786e-05 | I15: =Convolution!O215 -> 0.0013463735 | J15: =Convolution!O216 -> 0.0098545871 | K15: =Convolution!O217 -> 0.042417023 | L15: =Convolution!O218 -> 0.11674097 | M15: =Convolution!O219 -> 0.21329781 | N15: =Convolution!O220 -> 0.26124974 | O15: =Convolution!O221 -> 0.21144984 | P15: =Convolution!O222 -> 0.10810196 | Q15: =Convolution!O223 -> 0.031487549 | R15: =Convolution!O224 -> 0.0039634817 | S15: =Convolution!O225 -> 0 | T15: =INDEX($F$1:$S$1,MATCH(MAX(F15:S15),F15:S15,0)) -> P(8) | U15: =SUM(L15:S15) -> 0.94629136 | V15: =SUM(P15:S15) -> 0.14355299 | W15: =ROUND(SUM(F15:S15),6) -> 1
A16: =RANK(E16,$E$2:$E$139) -> 44 | B16: Michigan | C16: =Schedule!$B$16 -> 17 | D16: 12 | E16: =Schedule!$BQ$16 -> 7.4486927 | F16: =Convolution!O228 -> 2.8003627e-08 | G16: =Convolution!O229 -> 4.6976779e-06 | H16: =Convolution!O230 -> 0.00015351515 | I16: =Convolution!O231 -> 0.0020779361 | J16: =Convolution!O232 -> 0.014875434 | K16: =Convolution!O233 -> 0.062617352 | L16: =Convolution!O234 -> 0.16268263 | M16: =Convolution!O235 -> 0.26497923 | N16: =Convolution!O236 -> 0.26781325 | O16: =Convolution!O237 -> 0.16161324 | P16: =Convolution!O238 -> 0.053946585 | Q16: =Convolution!O239 -> 0.0087159566 | R16: =Convolution!O240 -> 0.00052014285 | S16: =Convolution!O241 -> 0 | T16: =INDEX($F$1:$S$1,MATCH(MAX(F16:S16),F16:S16,0)) -> P(8) | U16: =SUM(L16:S16) -> 0.92027104 | V16: =SUM(P16:S16) -> 0.063182685 | W16: =ROUND(SUM(F16:S16),6) -> 1
A17: =RANK(E17,$E$2:$E$139) -> 51 | B17: Ole Miss | C17: =Schedule!$B$17 -> 16.5 | D17: 12 | E17: =Schedule!$BQ$17 -> 7.2433672 | F17: =Convolution!O244 -> 1.1718619e-09 | G17: =Convolution!O245 -> 1.4140253e-06 | H17: =Convolution!O246 -> 0.0003210792 | I17: =Convolution!O247 -> 0.0044542322 | J17: =Convolution!O248 -> 0.026641192 | K17: =Convolution!O249 -> 0.089615591 | L17: =Convolution!O250 -> 0.18797281 | M17: =Convolution!O251 -> 0.25728524 | N17: =Convolution!O252 -> 0.23297179 | O17: =Convolution!O253 -> 0.13791814 | P17: =Convolution!O254 -> 0.051124729 | Q17: =Convolution!O255 -> 0.010725548 | R17: =Convolution!O256 -> 0.00096823566 | S17: =Convolution!O257 -> 0 | T17: =INDEX($F$1:$S$1,MATCH(MAX(F17:S17),F17:S17,0)) -> P(7) | U17: =SUM(L17:S17) -> 0.87896649 | V17: =SUM(P17:S17) -> 0.062818512 | W17: =ROUND(SUM(F17:S17),6) -> 1
A18: =RANK(E18,$E$2:$E$139) -> 8 | B18: Penn St. | C18: =Schedule!$B$18 -> 16.2 | D18: 12 | E18: =Schedule!$BQ$18 -> 9.0020535 | F18: =Convolution!O260 -> 6.9177251e-10 | G18: =Convolution!O261 -> 7.0698447e-08 | H18: =Convolution!O262 -> 2.826765e-06 | I18: =Convolution!O263 -> 5.93563e-05 | J18: =Convolution!O264 -> 0.00073739806 | K18: =Convolution!O265 -> 0.0057571673 | L18: =Convolution!O266 -> 0.02914279 | M18: =Convolution!O267 -> 0.0967472 | N18: =Convolution!O268 -> 0.20944249 | O18: =Convolution!O269 -> 0.28850536 | P18: =Convolution!O270 -> 0.24019231 | Q18: =Convolution!O271 -> 0.10892046 | R18: =Convolution!O272 -> 0.020492569 | S18: =Convolution!O273 -> 0 | T18: =INDEX($F$1:$S$1,MATCH(MAX(F18:S18),F18:S18,0)) -> P(9) | U18: =SUM(L18:S18) -> 0.99344318 | V18: =SUM(P18:S18) -> 0.36960533 | W18: =ROUND(SUM(F18:S18),6) -> 1
A19: =RANK(E19,$E$2:$E$139) -> 30 | B19: Washington | C19: =Schedule!$B$19 -> 15.8 | D19: 12 | E19: =Schedule!$BQ$19 -> 7.8392732 | F19: =Convolution!O276 -> 9.1994287e-09 | G19: =Convolution!O277 -> 1.359011e-06 | H19: =Convolution!O278 -> 5.1613677e-05 | I19: =Convolution!O279 -> 0.00085986676 | J19: =Convolution!O280 -> 0.0075322548 | K19: =Convolution!O281 -> 0.038267525 | L19: =Convolution!O282 -> 0.11884776 | M19: =Convolution!O283 -> 0.231013 | N19: =Convolution!O284 -> 0.28138286 | O19: =Convolution!O285 -> 0.20987249 | P19: =Convolution!O286 -> 0.090512935 | Q19: =Convolution!O287 -> 0.019999743 | R19: =Convolution!O288 -> 0.001658587 | S19: =Convolution!O289 -> 0 | T19: =INDEX($F$1:$S$1,MATCH(MAX(F19:S19),F19:S19,0)) -> P(8) | U19: =SUM(L19:S19) -> 0.95328737 | V19: =SUM(P19:S19) -> 0.11217127 | W19: =ROUND(SUM(F19:S19),6) -> 1
A20: =RANK(E20,$E$2:$E$139) -> 49 | B20: Missouri | C20: =Schedule!$B$20 -> 15.4 | D20: 12 | E20: =Schedule!$BQ$20 -> 7.2890999 | F20: =Convolution!O292 -> 1.0573037e-09 | G20: =Convolution!O293 -> 1.1697965e-05 | H20: =Convolution!O294 -> 0.00038709899 | I20: =Convolution!O295 -> 0.0043343045 | J20: =Convolution!O296 -> 0.0248056 | K20: =Convolution!O297 -> 0.084270365 | L20: =Convolution!O298 -> 0.18188662 | M20: =Convolution!O299 -> 0.25696686 | N20: =Convolution!O300 -> 0.23889281 | O20: =Convolution!O301 -> 0.14358737 | P20: =Convolution!O302 -> 0.053118606 | Q20: =Convolution!O303 -> 0.010829765 | R20: =Convolution!O304 -> 0.00090889862 | S20: =Convolution!O305 -> 0 | T20: =INDEX($F$1:$S$1,MATCH(MAX(F20:S20),F20:S20,0)) -> P(7) | U20: =SUM(L20:S20) -> 0.88619093 | V20: =SUM(P20:S20) -> 0.064857269 | W20: =ROUND(SUM(F20:S20),6) -> 1
A21: =RANK(E21,$E$2:$E$139) -> 59 | B21: Florida | C21: =Schedule!$B$21 -> 15.2 | D21: 12 | E21: =Schedule!$BQ$21 -> 6.9833691 | F21: =Convolution!O308 -> 1.2186021e-07 | G21: =Convolution!O309 -> 4.1631613e-05 | H21: =Convolution!O310 -> 0.0010153443 | I21: =Convolution!O311 -> 0.0088730125 | J21: =Convolution!O312 -> 0.040844383 | K21: =Convolution!O313 -> 0.11452648 | L21: =Convolution!O314 -> 0.20906324 | M21: =Convolution!O315 -> 0.25562386 | N21: =Convolution!O316 -> 0.21002437 | O21: =Convolution!O317 -> 0.1136304 | P21: =Convolution!O318 -> 0.038464251 | Q21: =Convolution!O319 -> 0.0073045939 | R21: =Convolution!O320 -> 0.00058830543 | S21: =Convolution!O321 -> 0 | T21: =INDEX($F$1:$S$1,MATCH(MAX(F21:S21),F21:S21,0)) -> P(7) | U21: =SUM(L21:S21) -> 0.83469903 | V21: =SUM(P21:S21) -> 0.04635715 | W21: =ROUND(SUM(F21:S21),6) -> 1
A22: =RANK(E22,$E$2:$E$139) -> 12 | B22: BYU | C22: =Schedule!$B$22 -> 14.9 | D22: 12 | E22: =Schedule!$BQ$22 -> 8.7767052 | F22: =Convolution!O324 -> 1.6937256e-10 | G22: =Convolution!O325 -> 2.1464399e-07 | H22: =Convolution!O326 -> 9.1147554e-06 | I22: =Convolution!O327 -> 0.00016374775 | J22: =Convolution!O328 -> 0.0016498965 | K22: =Convolution!O329 -> 0.010415829 | L22: =Convolution!O330 -> 0.043368518 | M22: =Convolution!O331 -> 0.12150775 | N22: =Convolution!O332 -> 0.22843332 | O22: =Convolution!O333 -> 0.28070238 | P22: =Convolution!O334 -> 0.21238568 | Q22: =Convolution!O335 -> 0.087255915 | R22: =Convolution!O336 -> 0.014107623 | S22: =Convolution!O337 -> 0 | T22: =INDEX($F$1:$S$1,MATCH(MAX(F22:S22),F22:S22,0)) -> P(9) | U22: =SUM(L22:S22) -> 0.9877612 | V22: =SUM(P22:S22) -> 0.31374922 | W22: =ROUND(SUM(F22:S22),6) -> 1
A23: =RANK(E23,$E$2:$E$139) -> 24 | B23: Iowa | C23: =Schedule!$B$23 -> 14.6 | D23: 12 | E23: =Schedule!$BQ$23 -> 8.0031218 | F23: =Convolution!O340 -> 5.8823277e-09 | G23: =Convolution!O341 -> 7.7487366e-07 | H23: =Convolution!O342 -> 3.3972574e-05 | I23: =Convolution!O343 -> 0.00061121344 | J23: =Convolution!O344 -> 0.0056889081 | K23: =Convolution!O345 -> 0.030686544 | L23: =Convolution!O346 -> 0.10168936 | M23: =Convolution!O347 -> 0.21262624 | N23: =Convolution!O348 -> 0.28107286 | O23: =Convolution!O349 -> 0.22943688 | P23: =Convolution!O350 -> 0.10909504 | Q23: =Convolution!O351 -> 0.026652345 | R23: =Convolution!O352 -> 0.002405853 | S23: =Convolution!O353 -> 0 | T23: =INDEX($F$1:$S$1,MATCH(MAX(F23:S23),F23:S23,0)) -> P(8) | U23: =SUM(L23:S23) -> 0.96297858 | V23: =SUM(P23:S23) -> 0.13815324 | W23: =ROUND(SUM(F23:S23),6) -> 1
A24: =RANK(E24,$E$2:$E$139) -> 26 | B24: Clemson | C24: =Schedule!$B$24 -> 13.1 | D24: 12 | E24: =Schedule!$BQ$24 -> 7.9361046 | F24: =Convolution!O356 -> 2.3755891e-09 | G24: =Convolution!O357 -> 2.543424e-06 | H24: =Convolution!O358 -> 9.4853534e-05 | I24: =Convolution!O359 -> 0.0012850575 | J24: =Convolution!O360 -> 0.0091958182 | K24: =Convolution!O361 -> 0.040018253 | L24: =Convolution!O362 -> 0.11291769 | M24: =Convolution!O363 -> 0.21212625 | N24: =Convolution!O364 -> 0.26557891 | O24: =Convolution!O365 -> 0.21653082 | P24: =Convolution!O366 -> 0.10878977 | Q24: =Convolution!O367 -> 0.030034008 | R24: =Convolution!O368 -> 0.0034260248 | S24: =Convolution!O369 -> 0 | T24: =INDEX($F$1:$S$1,MATCH(MAX(F24:S24),F24:S24,0)) -> P(8) | U24: =SUM(L24:S24) -> 0.94940347 | V24: =SUM(P24:S24) -> 0.1422498 | W24: =ROUND(SUM(F24:S24),6) -> 1
A25: =RANK(E25,$E$2:$E$139) -> 70 | B25: S. Carolina | C25: =Schedule!$B$25 -> 12.6 | D25: 12 | E25: =Schedule!$BQ$25 -> 6.5255292 | F25: =Convolution!O372 -> 6.1655629e-08 | G25: =Convolution!O373 -> 1.9098708e-05 | H25: =Convolution!O374 -> 0.0014538679 | I25: =Convolution!O375 -> 0.014727711 | J25: =Convolution!O376 -> 0.06582353 | K25: =Convolution!O377 -> 0.16401421 | L25: =Convolution!O378 -> 0.25151112 | M25: =Convolution!O379 -> 0.24917059 | N25: =Convolution!O380 -> 0.16248117 | O25: =Convolution!O381 -> 0.069243444 | P25: =Convolution!O382 -> 0.0185412 | Q25: =Convolution!O383 -> 0.0028270844 | R25: =Convolution!O384 -> 0.00018691023 | S25: =Convolution!O385 -> 0 | T25: =INDEX($F$1:$S$1,MATCH(MAX(F25:S25),F25:S25,0)) -> P(6) | U25: =SUM(L25:S25) -> 0.75396152 | V25: =SUM(P25:S25) -> 0.021555194 | W25: =ROUND(SUM(F25:S25),6) -> 1
A26: =RANK(E26,$E$2:$E$139) -> 16 | B26: SMU | C26: =Schedule!$B$26 -> 12.1 | D26: 12 | E26: =Schedule!$BQ$26 -> 8.2912458 | F26: =Convolution!O388 -> 6.688514e-09 | G26: =Convolution!O389 -> 7.4108738e-07 | H26: =Convolution!O390 -> 2.730435e-05 | I26: =Convolution!O391 -> 0.00044256623 | J26: =Convolution!O392 -> 0.0039391674 | K26: =Convolution!O393 -> 0.021481811 | L26: =Convolution!O394 -> 0.075696766 | M26: =Convolution!O395 -> 0.17585274 | N26: =Convolution!O396 -> 0.26792791 | O26: =Convolution!O397 -> 0.25928911 | P26: =Convolution!O398 -> 0.14832529 | Q26: =Convolution!O399 -> 0.042929945 | R26: =Convolution!O400 -> 0.0040866447 | S26: =Convolution!O401 -> 0 | T26: =INDEX($F$1:$S$1,MATCH(MAX(F26:S26),F26:S26,0)) -> P(8) | U26: =SUM(L26:S26) -> 0.9741084 | V26: =SUM(P26:S26) -> 0.19534188 | W26: =ROUND(SUM(F26:S26),6) -> 1
A27: =RANK(E27,$E$2:$E$139) -> 72 | B27: Auburn | C27: =Schedule!$B$27 -> 11.5 | D27: 12 | E27: =Schedule!$BQ$27 -> 6.4442188 | F27: =Convolution!O404 -> 6.6690194e-08 | G27: =Convolution!O405 -> 2.7375459e-05 | H27: =Convolution!O406 -> 0.0017421238 | I27: =Convolution!O407 -> 0.016501588 | J27: =Convolution!O408 -> 0.070735745 | K27: =Convolution!O409 -> 0.17165576 | L27: =Convolution!O410 -> 0.25752336 | M27: =Convolution!O411 -> 0.24801545 | N27: =Convolution!O412 -> 0.15484429 | O27: =Convolution!O413 -> 0.061790568 | P27: =Convolution!O414 -> 0.015047151 | Q27: =Convolution!O415 -> 0.0020068555 | R27: =Convolution!O416 -> 0.00010966678 | S27: =Convolution!O417 -> 0 | T27: =INDEX($F$1:$S$1,MATCH(MAX(F27:S27),F27:S27,0)) -> P(6) | U27: =SUM(L27:S27) -> 0.73933734 | V27: =SUM(P27:S27) -> 0.017163674 | W27: =ROUND(SUM(F27:S27),6) -> 1
A28: =RANK(E28,$E$2:$E$139) -> 29 | B28: Louisville | C28: =Schedule!$B$28 -> 11.1 | D28: 12 | E28: =Schedule!$BQ$28 -> 7.8401589 | F28: =Convolution!O420 -> 2.7429706e-07 | G28: =Convolution!O421 -> 1.7155073e-05 | H28: =Convolution!O422 -> 0.00030388752 | I28: =Convolution!O423 -> 0.002703087 | J28: =Convolution!O424 -> 0.014529317 | K28: =Convolution!O425 -> 0.051379478 | L28: =Convolution!O426 -> 0.12470362 | M28: =Convolution!O427 -> 0.21144047 | N28: =Convolution!O428 -> 0.25011259 | O28: =Convolution!O429 -> 0.20204187 | P28: =Convolution!O430 -> 0.10598671 | Q28: =Convolution!O431 -> 0.032418035 | R28: =Convolution!O432 -> 0.0043634966 | S28: =Convolution!O433 -> 0 | T28: =INDEX($F$1:$S$1,MATCH(MAX(F28:S28),F28:S28,0)) -> P(8) | U28: =SUM(L28:S28) -> 0.9310668 | V28: =SUM(P28:S28) -> 0.14276824 | W28: =ROUND(SUM(F28:S28),6) -> 1
A29: =RANK(E29,$E$2:$E$139) -> 58 | B29: Illinois | C29: =Schedule!$B$29 -> 10.4 | D29: 12 | E29: =Schedule!$BQ$29 -> 7.0330811 | F29: =Convolution!O436 -> 3.4036122e-07 | G29: =Convolution!O437 -> 2.4690252e-05 | H29: =Convolution!O438 -> 0.00059929267 | I29: =Convolution!O439 -> 0.0060669409 | J29: =Convolution!O440 -> 0.03239833 | K29: =Convolution!O441 -> 0.10316435 | L29: =Convolution!O442 -> 0.20796463 | M29: =Convolution!O443 -> 0.27113153 | N29: =Convolution!O444 -> 0.22636112 | O29: =Convolution!O445 -> 0.11558034 | P29: =Convolution!O446 -> 0.032523536 | Q29: =Convolution!O447 -> 0.0040327378 | R29: =Convolution!O448 -> 0.00015216503 | S29: =Convolution!O449 -> 0 | T29: =INDEX($F$1:$S$1,MATCH(MAX(F29:S29),F29:S29,0)) -> P(7) | U29: =SUM(L29:S29) -> 0.85774606 | V29: =SUM(P29:S29) -> 0.036708439 | W29: =ROUND(SUM(F29:S29),6) -> 1
A30: =RANK(E30,$E$2:$E$139) -> 75 | B30: Vanderbilt | C30: =Schedule!$B$30 -> 9.8 | D30: 12 | E30: =Schedule!$BQ$30 -> 6.3441841 | F30: =Convolution!O452 -> 2.6169897e-07 | G30: =Convolution!O453 -> 0.00011938921 | H30: =Convolution!O454 -> 0.0029634851 | I30: =Convolution!O455 -> 0.022086727 | J30: =Convolution!O456 -> 0.08225736 | K30: =Convolution!O457 -> 0.18133003 | L30: =Convolution!O458 -> 0.25503142 | M30: =Convolution!O459 -> 0.2364682 | N30: =Convolution!O460 -> 0.14536544 | O30: =Convolution!O461 -> 0.058082953 | P30: =Convolution!O462 -> 0.014281288 | Q30: =Convolution!O463 -> 0.0019122264 | R30: =Convolution!O464 -> 0.00010122032 | S30: =Convolution!O465 -> 0 | T30: =INDEX($F$1:$S$1,MATCH(MAX(F30:S30),F30:S30,0)) -> P(6) | U30: =SUM(L30:S30) -> 0.71124274 | V30: =SUM(P30:S30) -> 0.016294734 | W30: =ROUND(SUM(F30:S30),6) -> 1
A31: =RANK(E31,$E$2:$E$139) -> 27 | B31: Utah | C31: =Schedule!$B$31 -> 9.8 | D31: 12 | E31: =Schedule!$BQ$31 -> 7.9300236 | F31: =Convolution!O468 -> 2.4140706e-07 | G31: =Convolution!O469 -> 1.1729105e-05 | H31: =Convolution!O470 -> 0.00021376567 | I31: =Convolution!O471 -> 0.0020450985 | J31: =Convolution!O472 -> 0.011864088 | K31: =Convolution!O473 -> 0.044975541 | L31: =Convolution!O474 -> 0.1159007 | M31: =Convolution!O475 -> 0.2064986 | N31: =Convolution!O476 -> 0.25403519 | O31: =Convolution!O477 -> 0.21133206 | P31: =Convolution!O478 -> 0.11319401 | Q31: =Convolution!O479 -> 0.035137242 | R31: =Convolution!O480 -> 0.0047917288 | S31: =Convolution!O481 -> 0 | T31: =INDEX($F$1:$S$1,MATCH(MAX(F31:S31),F31:S31,0)) -> P(8) | U31: =SUM(L31:S31) -> 0.94088954 | V31: =SUM(P31:S31) -> 0.15312298 | W31: =ROUND(SUM(F31:S31),6) -> 1
A32: =RANK(E32,$E$2:$E$139) -> 40 | B32: Arizona | C32: =Schedule!$B$32 -> 9.5 | D32: 12 | E32: =Schedule!$BQ$32 -> 7.6277616 | F32: =Convolution!O484 -> 4.4564736e-08 | G32: =Convolution!O485 -> 5.1099708e-06 | H32: =Convolution!O486 -> 0.00016895115 | I32: =Convolution!O487 -> 0.0021306862 | J32: =Convolution!O488 -> 0.014126346 | K32: =Convolution!O489 -> 0.056355694 | L32: =Convolution!O490 -> 0.14389055 | M32: =Convolution!O491 -> 0.24083569 | N32: =Convolution!O492 -> 0.26368225 | O32: =Convolution!O493 -> 0.18376767 | P32: =Convolution!O494 -> 0.076676752 | Q32: =Convolution!O495 -> 0.016908028 | R32: =Convolution!O496 -> 0.001452226 | S32: =Convolution!O497 -> 0 | T32: =INDEX($F$1:$S$1,MATCH(MAX(F32:S32),F32:S32,0)) -> P(8) | U32: =SUM(L32:S32) -> 0.92721317 | V32: =SUM(P32:S32) -> 0.095037007 | W32: =ROUND(SUM(F32:S32),6) -> 1
A33: =RANK(E33,$E$2:$E$139) -> 45 | B33: TCU | C33: =Schedule!$B$33 -> 9.4 | D33: 12 | E33: =Schedule!$BQ$33 -> 7.4320158 | F33: =Convolution!O500 -> 1.3991027e-08 | G33: =Convolution!O501 -> 1.286964e-05 | H33: =Convolution!O502 -> 0.00035951651 | I33: =Convolution!O503 -> 0.0038084361 | J33: =Convolution!O504 -> 0.021494989 | K33: =Convolution!O505 -> 0.073962754 | L33: =Convolution!O506 -> 0.165357 | M33: =Convolution!O507 -> 0.24686461 | N33: =Convolution!O508 -> 0.24659616 | O33: =Convolution!O509 -> 0.1610799 | P33: =Convolution!O510 -> 0.06495559 | Q33: =Convolution!O511 -> 0.014271633 | R33: =Convolution!O512 -> 0.0012365361 | S33: =Convolution!O513 -> 0 | T33: =INDEX($F$1:$S$1,MATCH(MAX(F33:S33),F33:S33,0)) -> P(7) | U33: =SUM(L33:S33) -> 0.90036142 | V33: =SUM(P33:S33) -> 0.080463758 | W33: =ROUND(SUM(F33:S33),6) -> 1
A34: =RANK(E34,$E$2:$E$139) -> 77 | B34: Nebraska | C34: =Schedule!$B$34 -> 9.3 | D34: 12 | E34: =Schedule!$BQ$34 -> 6.1726306 | F34: =Convolution!O516 -> 2.1700013e-06 | G34: =Convolution!O517 -> 0.0001146098 | H34: =Convolution!O518 -> 0.0022227986 | I34: =Convolution!O519 -> 0.019815304 | J34: =Convolution!O520 -> 0.085918803 | K34: =Convolution!O521 -> 0.20409555 | L34: =Convolution!O522 -> 0.28438038 | M34: =Convolution!O523 -> 0.23918515 | N34: =Convolution!O524 -> 0.12150121 | O34: =Convolution!O525 -> 0.036274922 | P34: =Convolution!O526 -> 0.0059860836 | Q34: =Convolution!O527 -> 0.00048787375 | R34: =Convolution!O528 -> 1.5147472e-05 | S34: =Convolution!O529 -> 0 | T34: =INDEX($F$1:$S$1,MATCH(MAX(F34:S34),F34:S34,0)) -> P(6) | U34: =SUM(L34:S34) -> 0.68783077 | V34: =SUM(P34:S34) -> 0.0064891048 | W34: =ROUND(SUM(F34:S34),6) -> 1
A35: =RANK(E35,$E$2:$E$139) -> 22 | B35: Kansas St. | C35: =Schedule!$B$35 -> 9.2 | D35: 12 | E35: =Schedule!$BQ$35 -> 8.0436345 | F35: =Convolution!O532 -> 2.8394872e-08 | G35: =Convolution!O533 -> 6.8745136e-06 | H35: =Convolution!O534 -> 0.00015950763 | I35: =Convolution!O535 -> 0.0016708977 | J35: =Convolution!O536 -> 0.010170967 | K35: =Convolution!O537 -> 0.039911881 | L35: =Convolution!O538 -> 0.10622277 | M35: =Convolution!O539 -> 0.19611592 | N35: =Convolution!O540 -> 0.25169755 | O35: =Convolution!O541 -> 0.22040511 | P35: =Convolution!O542 -> 0.12554718 | Q35: =Convolution!O543 -> 0.041889433 | R35: =Convolution!O544 -> 0.0062018904 | S35: =Convolution!O545 -> 0 | T35: =INDEX($F$1:$S$1,MATCH(MAX(F35:S35),F35:S35,0)) -> P(8) | U35: =SUM(L35:S35) -> 0.94807984 | V35: =SUM(P35:S35) -> 0.1736385 | W35: =ROUND(SUM(F35:S35),6) -> 1
A36: =RANK(E36,$E$2:$E$139) -> 68 | B36: Florida St. | C36: =Schedule!$B$36 -> 9.1 | D36: 12 | E36: =Schedule!$BQ$36 -> 6.5842999 | F36: =Convolution!O548 -> 2.1366911e-07 | G36: =Convolution!O549 -> 4.7211809e-05 | H36: =Convolution!O550 -> 0.0017122352 | I36: =Convolution!O551 -> 0.015017514 | J36: =Convolution!O552 -> 0.063274629 | K36: =Convolution!O553 -> 0.15574497 | L36: =Convolution!O554 -> 0.24339031 | M36: =Convolution!O555 -> 0.25033943 | N36: =Convolution!O556 -> 0.17066849 | O36: =Convolution!O557 -> 0.075705132 | P36: =Convolution!O558 -> 0.020756175 | Q36: =Convolution!O559 -> 0.0031457371 | R36: =Convolution!O560 -> 0.00019795543 | S36: =Convolution!O561 -> 0 | T36: =INDEX($F$1:$S$1,MATCH(MAX(F36:S36),F36:S36,0)) -> P(7) | U36: =SUM(L36:S36) -> 0.76420323 | V36: =SUM(P36:S36) -> 0.024099868 | W36: =ROUND(SUM(F36:S36),6) -> 1
A37: =RANK(E37,$E$2:$E$139) -> 55 | B37: Va. Tech | C37: =Schedule!$B$37 -> 8.6 | D37: 12 | E37: =Schedule!$BQ$37 -> 7.1372958 | F37: =Convolution!O564 -> 6.7774513e-08 | G37: =Convolution!O565 -> 3.5602544e-05 | H37: =Convolution!O566 -> 0.00074333781 | I37: =Convolution!O567 -> 0.0065602773 | J37: =Convolution!O568 -> 0.032200924 | K37: =Convolution!O569 -> 0.098049104 | L37: =Convolution!O570 -> 0.19491952 | M37: =Convolution!O571 -> 0.25808731 | N37: =Convolution!O572 -> 0.22688085 | O37: =Convolution!O573 -> 0.12893194 | P37: =Convolution!O574 -> 0.044637868 | Q37: =Convolution!O575 -> 0.0083361545 | R37: =Convolution!O576 -> 0.0006170538 | S37: =Convolution!O577 -> 0 | T37: =INDEX($F$1:$S$1,MATCH(MAX(F37:S37),F37:S37,0)) -> P(7) | U37: =SUM(L37:S37) -> 0.86241069 | V37: =SUM(P37:S37) -> 0.053591076 | W37: =ROUND(SUM(F37:S37),6) -> 1
A38: =RANK(E38,$E$2:$E$139) -> 34 | B38: Virginia | C38: =Schedule!$B$38 -> 8.1 | D38: 12 | E38: =Schedule!$BQ$38 -> 7.7652962 | F38: =Convolution!O580 -> 6.1258422e-09 | G38: =Convolution!O581 -> 6.5084508e-06 | H38: =Convolution!O582 -> 0.00019171151 | I38: =Convolution!O583 -> 0.0021964639 | J38: =Convolution!O584 -> 0.013640272 | K38: =Convolution!O585 -> 0.052301869 | L38: =Convolution!O586 -> 0.13166105 | M38: =Convolution!O587 -> 0.22351251 | N38: =Convolution!O588 -> 0.25676692 | O38: =Convolution!O589 -> 0.19592631 | P38: =Convolution!O590 -> 0.094639574 | Q38: =Convolution!O591 -> 0.026057043 | R38: =Convolution!O592 -> 0.0030997665 | S38: =Convolution!O593 -> 0 | T38: =INDEX($F$1:$S$1,MATCH(MAX(F38:S38),F38:S38,0)) -> P(8) | U38: =SUM(L38:S38) -> 0.93166317 | V38: =SUM(P38:S38) -> 0.12379638 | W38: =ROUND(SUM(F38:S38),6) -> 1
A39: =RANK(E39,$E$2:$E$139) -> 47 | B39: Houston | C39: =Schedule!$B$39 -> 7.4 | D39: 12 | E39: =Schedule!$BQ$39 -> 7.4278394 | F39: =Convolution!O596 -> 3.0896622e-08 | G39: =Convolution!O597 -> 1.8966077e-05 | H39: =Convolution!O598 -> 0.00041671183 | I39: =Convolution!O599 -> 0.0039748636 | J39: =Convolution!O600 -> 0.021505159 | K39: =Convolution!O601 -> 0.073216556 | L39: =Convolution!O602 -> 0.1644549 | M39: =Convolution!O603 -> 0.247825 | N39: =Convolution!O604 -> 0.24898354 | O39: =Convolution!O605 -> 0.16174073 | P39: =Convolution!O606 -> 0.06360798 | Q39: =Convolution!O607 -> 0.013226802 | R39: =Convolution!O608 -> 0.0010287543 | S39: =Convolution!O609 -> 0 | T39: =INDEX($F$1:$S$1,MATCH(MAX(F39:S39),F39:S39,0)) -> P(8) | U39: =SUM(L39:S39) -> 0.90086771 | V39: =SUM(P39:S39) -> 0.077863536 | W39: =ROUND(SUM(F39:S39),6) -> 1
A40: =RANK(E40,$E$2:$E$139) -> 67 | B40: Oklahoma St. | C40: =Schedule!$B$40 -> 6.9 | D40: 12 | E40: =Schedule!$BQ$40 -> 6.6256977 | F40: =Convolution!O612 -> 5.5098952e-06 | G40: =Convolution!O613 -> 0.00022473904 | H40: =Convolution!O614 -> 0.0027299446 | I40: =Convolution!O615 -> 0.016764143 | J40: =Convolution!O616 -> 0.061766673 | K40: =Convolution!O617 -> 0.14717513 | L40: =Convolution!O618 -> 0.23433928 | M40: =Convolution!O619 -> 0.25117081 | N40: =Convolution!O620 -> 0.17881339 | O40: =Convolution!O621 -> 0.081531179 | P40: =Convolution!O622 -> 0.022178471 | Q40: =Convolution!O623 -> 0.0031342513 | R40: =Convolution!O624 -> 0.00016647358 | S40: =Convolution!O625 -> 0 | T40: =INDEX($F$1:$S$1,MATCH(MAX(F40:S40),F40:S40,0)) -> P(7) | U40: =SUM(L40:S40) -> 0.77133386 | V40: =SUM(P40:S40) -> 0.025479196 | W40: =ROUND(SUM(F40:S40),6) -> 1
...

Sheet Market_Edge
A1: Team | B1: Line | C1: Over Odds | D1: Under Odds | E1: Model Exp W | F1: Model P(Over) | G1: Mkt P(Over) raw | H1: Mkt P(Under) raw | I1: Vig | J1: Fair P(Over) | K1: Edge (Over) | L1: Bet | M1: Bet Prob | N1: Bet Price | O1: EV per $100 | P1: Kelly %
A2: Ohio St. | B2: 9.5 | C2: -166 | D2: 140 | E2: =Win_Probabilities!E2 -> 10.205967 | F2: =SUMPRODUCT((Win_Probabilities!$F$1:$S$1<>"")*(COLUMN(Win_Probabilities!$F$1:$S$1)-COLUMN(Win_Probabilities!$F$1)>$B2)*Win_Probabilities!$F2:$S2) -> 0.74659984 | G2: =IF(C2<0,-C2/(-C2+100),100/(C2+100)) -> 0.62406015 | H2: =IF(D2<0,-D2/(-D2+100),100/(D2+100)) -> 0.41666667 | I2: =G2+H2-1 -> 0.040726817 | J2: =G2/(G2+H2) -> 0.59963877 | K2: =F2-J2 -> 0.14696106 | L2: =IF(K2>0,"OVER","UNDER") -> OVER | M2: =IF(K2>0,F2,1-F2) -> 0.74659984 | N2: =IF(K2>0,C2,D2) -> -166 | O2: =M2*IF(N2<0,10000/-N2,N2)-(1-M2)*100 -> 19.635877 | P2: =MAX(0,(M2*(IF(N2<0,100/-N2,N2/100)+1)-1)/IF(N2<0,100/-N2,N2/100)) -> 0.32595556
A3: Oregon | B3: 10.5 | C3: 100 | D3: -120 | E3: =Win_Probabilities!E3 -> 10.175094 | F3: =SUMPRODUCT((Win_Probabilities!$F$1:$S$1<>"")*(COLUMN(Win_Probabilities!$F$1:$S$1)-COLUMN(Win_Probabilities!$F$1)>$B3)*Win_Probabilities!$F3:$S3) -> 0.4133802 | G3: =IF(C3<0,-C3/(-C3+100),100/(C3+100)) -> 0.5 | H3: =IF(D3<0,-D3/(-D3+100),100/(D3+100)) -> 0.54545455 | I3: =G3+H3-1 -> 0.045454545 | J3: =G3/(G3+H3) -> 0.47826087 | K3: =F3-J3 -> -0.064880671 | L3: =IF(K3>0,"OVER","UNDER") -> UNDER | M3: =IF(K3>0,F3,1-F3) -> 0.5866198 | N3: =IF(K3>0,C3,D3) -> -120 | O3: =M3*IF(N3<0,10000/-N3,N3)-(1-M3)*100 -> 7.5469636 | P3: =MAX(0,(M3*(IF(N3<0,100/-N3,N3/100)+1)-1)/IF(N3<0,100/-N3,N3/100)) -> 0.090563563
A4: Notre Dame | B4: 11.5 | C4: 160 | D4: -190 | E4: =Win_Probabilities!E4 -> 10.800983 | F4: =SUMPRODUCT((Win_Probabilities!$F$1:$S$1<>"")*(COLUMN(Win_Probabilities!$F$1:$S$1)-COLUMN(Win_Probabilities!$F$1)>$B4)*Win_Probabilities!$F4:$S4) -> 0.26006172 | G4: =IF(C4<0,-C4/(-C4+100),100/(C4+100)) -> 0.38461538 | H4: =IF(D4<0,-D4/(-D4+100),100/(D4+100)) -> 0.65517241 | I4: =G4+H4-1 -> 0.039787798 | J4: =G4/(G4+H4) -> 0.36989796 | K4: =F4-J4 -> -0.10983624 | L4: =IF(K4>0,"OVER","UNDER") -> UNDER | M4: =IF(K4>0,F4,1-F4) -> 0.73993828 | N4: =IF(K4>0,C4,D4) -> -190 | O4: =M4*IF(N4<0,10000/-N4,N4)-(1-M4)*100 -> 12.937948 | P4: =MAX(0,(M4*(IF(N4<0,100/-N4,N4/100)+1)-1)/IF(N4<0,100/-N4,N4/100)) -> 0.24582101
A5: Georgia | B5: 9.5 | C5: -180 | D5: 150 | E5: =Win_Probabilities!E5 -> 9.9177097 | F5: =SUMPRODUCT((Win_Probabilities!$F$1:$S$1<>"")*(COLUMN(Win_Probabilities!$F$1:$S$1)-COLUMN(Win_Probabilities!$F$1)>$B5)*Win_Probabilities!$F5:$S5) -> 0.65380909 | G5: =IF(C5<0,-C5/(-C5+100),100/(C5+100)) -> 0.64285714 | H5: =IF(D5<0,-D5/(-D5+100),100/(D5+100)) -> 0.4 | I5: =G5+H5-1 -> 0.042857143 | J5: =G5/(G5+H5) -> 0.61643836 | K5: =F5-J5 -> 0.037370733 | L5: =IF(K5>0,"OVER","UNDER") -> OVER | M5: =IF(K5>0,F5,1-F5) -> 0.65380909 | N5: =IF(K5>0,C5,D5) -> -180 | O5: =M5*IF(N5<0,10000/-N5,N5)-(1-M5)*100 -> 1.7036361 | P5: =MAX(0,(M5*(IF(N5<0,100/-N5,N5/100)+1)-1)/IF(N5<0,100/-N5,N5/100)) -> 0.03066545
A6: Indiana | B6: 10.5 | C6: 105 | D6: -125 | E6: =Win_Probabilities!E6 -> 9.9767659 | F6: =SUMPRODUCT((Win_Probabilities!$F$1:$S$1<>"")*(COLUMN(Win_Probabilities!$F$1:$S$1)-COLUMN(Win_Probabilities!$F$1)>$B6)*Win_Probabilities!$F6:$S6) -> 0.34161595 | G6: =IF(C6<0,-C6/(-C6+100),100/(C6+100)) -> 0.48780488 | H6: =IF(D6<0,-D6/(-D6+100),100/(D6+100)) -> 0.55555556 | I6: =G6+H6-1 -> 0.043360434 | J6: =G6/(G6+H6) -> 0.46753247 | K6: =F6-J6 -> -0.12591652 | L6: =IF(K6>0,"OVER","UNDER") -> UNDER | M6: =IF(K6>0,F6,1-F6) -> 0.65838405 | N6: =IF(K6>0,C6,D6) -> -125 | O6: =M6*IF(N6<0,10000/-N6,N6)-(1-M6)*100 -> 18.50913 | P6: =MAX(0,(M6*(IF(N6<0,100/-N6,N6/100)+1)-1)/IF(N6<0,100/-N6,N6/100)) -> 0.23136412
A7: Texas | B7: 9.5 | C7: 120 | D7: -142 | E7: =Win_Probabilities!E7 -> 8.2406365 | F7: =SUMPRODUCT((Win_Probabilities!$F$1:$S$1<>"")*(COLUMN(Win_Probabilities!$F$1:$S$1)-COLUMN(Win_Probabilities!$F$1)>$B7)*Win_Probabilities!$F7:$S7) -> 0.19421941 | G7: =IF(C7<0,-C7/(-C7+100),100/(C7+100)) -> 0.45454545 | H7: =IF(D7<0,-D7/(-D7+100),100/(D7+100)) -> 0.58677686 | I7: =G7+H7-1 -> 0.041322314 | J7: =G7/(G7+H7) -> 0.43650794 | K7: =F7-J7 -> -0.24228853 | L7: =IF(K7>0,"OVER","UNDER") -> UNDER | M7: =IF(K7>0,F7,1-F7) -> 0.80578059 | N7: =IF(K7>0,C7,D7) -> -142 | O7: =M7*IF(N7<0,10000/-N7,N7)-(1-M7)*100 -> 37.323171 | P7: =MAX(0,(M7*(IF(N7<0,100/-N7,N7/100)+1)-1)/IF(N7<0,100/-N7,N7/100)) -> 0.52998903
A8: Miami | B8: 10.5 | C8: -110 | D8: -110 | E8: =Win_Probabilities!E8 -> 9.9583102 | F8: =SUMPRODUCT((Win_Probabilities!$F$1:$S$1<>"")*(COLUMN(Win_Probabilities!$F$1:$S$1)-COLUMN(Win_Probabilities!$F$1)>$B8)*Win_Probabilities!$F8:$S8) -> 0.33987073 | G8: =IF(C8<0,-C8/(-C8+100),100/(C8+100)) -> 0.52380952 | H8: =IF(D8<0,-D8/(-D8+100),100/(D8+100)) -> 0.52380952 | I8: =G8+H8-1 -> 0.047619048 | J8: =G8/(G8+H8) -> 0.5 | K8: =F8-J8 -> -0.16012927 | L8: =IF(K8>0,"OVER","UNDER") -> UNDER | M8: =IF(K8>0,F8,1-F8) -> 0.66012927 | N8: =IF(K8>0,C8,D8) -> -110 | O8: =M8*IF(N8<0,10000/-N8,N8)-(1-M8)*100 -> 26.02468 | P8: =MAX(0,(M8*(IF(N8<0,100/-N8,N8/100)+1)-1)/IF(N8<0,100/-N8,N8/100)) -> 0.28627148
A9: Texas Tech | B9: 10.5 | C9: -200 | D9: 160 | E9: =Win_Probabilities!E9 -> 10.610496 | F9: =SUMPRODUCT((Win_Probabilities!$F$1:$S$1<>"")*(COLUMN(Win_Probabilities!$F$1:$S$1)-COLUMN(Win_Probabilities!$F$1)>$B9)*Win_Probabilities!$F9:$S9) -> 0.5843814 | G9: =IF(C9<0,-C9/(-C9+100),100/(C9+100)) -> 0.66666667 | H9: =IF(D9<0,-D9/(-D9+100),100/(D9+100)) -> 0.38461538 | I9: =G9+H9-1 -> 0.051282051 | J9: =G9/(G9+H9) -> 0.63414634 | K9: =F9-J9 -> -0.049764938 | L9: =IF(K9>0,"OVER","UNDER") -> UNDER | M9: =IF(K9>0,F9,1-F9) -> 0.4156186 | N9: =IF(K9>0,C9,D9) -> 160 | O9: =M9*IF(N9<0,10000/-N9,N9)-(1-M9)*100 -> 8.0608351 | P9: =MAX(0,(M9*(IF(N9<0,100/-N9,N9/100)+1)-1)/IF(N9<0,100/-N9,N9/100)) -> 0.05038022
A10: Texas A&M | B10: 8.5 | C10: 100 | D10: -120 | E10: =Win_Probabilities!E10 -> 8.4507633 | F10: =SUMPRODUCT((Win_Probabilities!$F$1:$S$1<>"")*(COLUMN(Win_Probabilities!$F$1:$S$1)-COLUMN(Win_Probabilities!$F$1)>$B10)*Win_Probabilities!$F10:$S10) -> 0.49573644 | G10: =IF(C10<0,-C10/(-C10+100),100/(C10+100)) -> 0.5 | H10: =IF(D10<0,-D10/(-D10+100),100/(D10+100)) -> 0.54545455 | I10: =G10+H10-1 -> 0.045454545 | J10: =G10/(G10+H10) -> 0.47826087 | K10: =F10-J10 -> 0.017475574 | L10: =IF(K10>0,"OVER","UNDER") -> OVER | M10: =IF(K10>0,F10,1-F10) -> 0.49573644 | N10: =IF(K10>0,C10,D10) -> 100 | O10: =M10*IF(N10<0,10000/-N10,N10)-(1-M10)*100 -> -0.85271137 | P10: =MAX(0,(M10*(IF(N10<0,100/-N10,N10/100)+1)-1)/IF(N10<0,100/-N10,N10/100)) -> 0
A11: LSU | B11: 8.5 | C11: -115 | D11: -105 | E11: =Win_Probabilities!E11 -> 8.5305373 | F11: =SUMPRODUCT((Win_Probabilities!$F$1:$S$1<>"")*(COLUMN(Win_Probabilities!$F$1:$S$1)-COLUMN(Win_Probabilities!$F$1)>$B11)*Win_Probabilities!$F11:$S11) -> 0.52083025 | G11: =IF(C11<0,-C11/(-C11+100),100/(C11+100)) -> 0.53488372 | H11: =IF(D11<0,-D11/(-D11+100),100/(D11+100)) -> 0.51219512 | I11: =G11+H11-1 -> 0.047078843 | J11: =G11/(G11+H11) -> 0.51083424 | K11: =F11-J11 -> 0.0099960127 | L11: =IF(K11>0,"OVER","UNDER") -> OVER | M11: =IF(K11>0,F11,1-F11) -> 0.52083025 | N11: =IF(K11>0,C11,D11) -> -115 | O11: =M11*IF(N11<0,10000/-N11,N11)-(1-M11)*100 -> -2.6273882 | P11: =MAX(0,(M11*(IF(N11<0,100/-N11,N11/100)+1)-1)/IF(N11<0,100/-N11,N11/100)) -> 0
A12: Oklahoma | B12: 7.5 | C12: -148 | D12: 124 | E12: =Win_Probabilities!E12 -> 7.5417647 | F12: =SUMPRODUCT((Win_Probabilities!$F$1:$S$1<>"")*(COLUMN(Win_Probabilities!$F$1:$S$1)-COLUMN(Win_Probabilities!$F$1)>$B12)*Win_Probabilities!$F12:$S12) -> 0.51653686 | G12: =IF(C12<0,-C12/(-C12+100),100/(C12+100)) -> 0.59677419 | H12: =IF(D12<0,-D12/(-D12+100),100/(D12+100)) -> 0.44642857 | I12: =G12+H12-1 -> 0.043202765 | J12: =G12/(G12+H12) -> 0.57205964 | K12: =F12-J12 -> -0.055522773 | L12: =IF(K12>0,"OVER","UNDER") -> UNDER | M12: =IF(K12>0,F12,1-F12) -> 0.48346314 | N12: =IF(K12>0,C12,D12) -> 124 | O12: =M12*IF(N12<0,10000/-N12,N12)-(1-M12)*100 -> 8.2957428 | P12: =MAX(0,(M12*(IF(N12<0,100/-N12,N12/100)+1)-1)/IF(N12<0,100/-N12,N12/100)) -> 0.066901152
A13: USC | B13: 8.5 | C13: 115 | D13: -136 | E13: =Win_Probabilities!E13 -> 7.8136586 | F13: =SUMPRODUCT((Win_Probabilities!$F$1:$S$1<>"")*(COLUMN(Win_Probabilities!$F$1:$S$1)-COLUMN(Win_Probabilities!$F$1)>$B13)*Win_Probabilities!$F13:$S13) -> 0.3095812 | G13: =IF(C13<0,-C13/(-C13+100),100/(C13+100)) -> 0.46511628 | H13: =IF(D13<0,-D13/(-D13+100),100/(D13+100)) -> 0.57627119 | I13: =G13+H13-1 -> 0.041387466 | J13: =G13/(G13+H13) -> 0.44663134 | K13: =F13-J13 -> -0.13705014 | L13: =IF(K13>0,"OVER","UNDER") -> UNDER | M13: =IF(K13>0,F13,1-F13) -> 0.6904188 | N13: =IF(K13>0,C13,D13) -> -136 | O13: =M13*IF(N13<0,10000/-N13,N13)-(1-M13)*100 -> 19.807967 | P13: =MAX(0,(M13*(IF(N13<0,100/-N13,N13/100)+1)-1)/IF(N13<0,100/-N13,N13/100)) -> 0.26938836
... A75: USF | B75: 8.5 | C75: 115 | D75: -145 | E75: =Win_Probabilities!E75 -> 8.1261067 | F75: =SUMPRODUCT((Win_Probabilities!$F$1:$S$1<>"")*(COLUMN(Win_Probabilities!$F$1:$S$1)-COLUMN(Win_Probabilities!$F$1)>$B75)*Win_Probabilities!$F75:$S75) -> 0.40827216 | G75: =IF(C75<0,-C75/(-C75+100),100/(C75+100)) -> 0.46511628 | H75: =IF(D75<0,-D75/(-D75+100),100/(D75+100)) -> 0.59183673 | I75: =G75+H75-1 -> 0.056953014 | J75: =G75/(G75+H75) -> 0.44005388 | K75: =F75-J75 -> -0.031781721 | L75: =IF(K75>0,"OVER","UNDER") -> UNDER | M75: =IF(K75>0,F75,1-F75) -> 0.59172784 | N75: =IF(K75>0,C75,D75) -> -145 | O75: =M75*IF(N75<0,10000/-N75,N75)-(1-M75)*100 -> -0.018400023 | P75: =MAX(0,(M75*(IF(N75<0,100/-N75,N75/100)+1)-1)/IF(N75<0,100/-N75,N75/100)) -> 0
A76: Syracuse | B76: 4.5 | C76: 105 | D76: -125 | E76: =Win_Probabilities!E77 -> 4.333179 | F76: =SUMPRODUCT((Win_Probabilities!$F$1:$S$1<>"")*(COLUMN(Win_Probabilities!$F$1:$S$1)-COLUMN(Win_Probabilities!$F$1)>$B76)*Win_Probabilities!$F77:$S77) -> 0.4402736 | G76: =IF(C76<0,-C76/(-C76+100),100/(C76+100)) -> 0.48780488 | H76: =IF(D76<0,-D76/(-D76+100),100/(D76+100)) -> 0.55555556 | I76: =G76+H76-1 -> 0.043360434 | J76: =G76/(G76+H76) -> 0.46753247 | K76: =F76-J76 -> -0.02725887 | L76: =IF(K76>0,"OVER","UNDER") -> UNDER | M76: =IF(K76>0,F76,1-F76) -> 0.5597264 | N76: =IF(K76>0,C76,D76) -> -125 | O76: =M76*IF(N76<0,10000/-N76,N76)-(1-M76)*100 -> 0.75075245 | P76: =MAX(0,(M76*(IF(N76<0,100/-N76,N76/100)+1)-1)/IF(N76<0,100/-N76,N76/100)) -> 0.0093844056
A77: Texas St. | B77: 6.5 | C77: 130 | D77: -165 | E77: =Win_Probabilities!E78 -> 6.7935671 | F77: =SUMPRODUCT((Win_Probabilities!$F$1:$S$1<>"")*(COLUMN(Win_Probabilities!$F$1:$S$1)-COLUMN(Win_Probabilities!$F$1)>$B77)*Win_Probabilities!$F78:$S78) -> 0.58306311 | G77: =IF(C77<0,-C77/(-C77+100),100/(C77+100)) -> 0.43478261 | H77: =IF(D77<0,-D77/(-D77+100),100/(D77+100)) -> 0.62264151 | I77: =G77+H77-1 -> 0.057424118 | J77: =G77/(G77+H77) -> 0.41117145 | K77: =F77-J77 -> 0.17189166 | L77: =IF(K77>0,"OVER","UNDER") -> OVER | M77: =IF(K77>0,F77,1-F77) -> 0.58306311 | N77: =IF(K77>0,C77,D77) -> 130 | O77: =M77*IF(N77<0,10000/-N77,N77)-(1-M77)*100 -> 34.104515 | P77: =MAX(0,(M77*(IF(N77<0,100/-N77,N77/100)+1)-1)/IF(N77<0,100/-N77,N77/100)) -> 0.26234242
A78: Purdue | B78: 3.5 | C78: 100 | D78: -120 | E78: =Win_Probabilities!E79 -> 3.3502003 | F78: =SUMPRODUCT((Win_Probabilities!$F$1:$S$1<>"")*(COLUMN(Win_Probabilities!$F$1:$S$1)-COLUMN(Win_Probabilities!$F$1)>$B78)*Win_Probabilities!$F79:$S79) -> 0.43754277 | G78: =IF(C78<0,-C78/(-C78+100),100/(C78+100)) -> 0.5 | H78: =IF(D78<0,-D78/(-D78+100),100/(D78+100)) -> 0.54545455 | I78: =G78+H78-1 -> 0.045454545 | J78: =G78/(G78+H78) -> 0.47826087 | K78: =F78-J78 -> -0.040718096 | L78: =IF(K78>0,"OVER","UNDER") -> UNDER | M78: =IF(K78>0,F78,1-F78) -> 0.56245723 | N78: =IF(K78>0,C78,D78) -> -120 | O78: =M78*IF(N78<0,10000/-N78,N78)-(1-M78)*100 -> 3.1171582 | P78: =MAX(0,(M78*(IF(N78<0,100/-N78,N78/100)+1)-1)/IF(N78<0,100/-N78,N78/100)) -> 0.037405899
A79: Stanford | B79: 3.5 | C79: -110 | D79: -110 | E79: =Win_Probabilities!E80 -> 3.8215696 | F79: =SUMPRODUCT((Win_Probabilities!$F$1:$S$1<>"")*(COLUMN(Win_Probabilities!$F$1:$S$1)-COLUMN(Win_Probabilities!$F$1)>$B79)*Win_Probabilities!$F80:$S80) -> 0.57441054 | G79: =IF(C79<0,-C79/(-C79+100),100/(C79+100)) -> 0.52380952 | H79: =IF(D79<0,-D79/(-D79+100),100/(D79+100)) -> 0.52380952 | I79: =G79+H79-1 -> 0.047619048 | J79: =G79/(G79+H79) -> 0.5 | K79: =F79-J79 -> 0.074410541 | L79: =IF(K79>0,"OVER","UNDER") -> OVER | M79: =IF(K79>0,F79,1-F79) -> 0.57441054 | N79: =IF(K79>0,C79,D79) -> -110 | O79: =M79*IF(N79<0,10000/-N79,N79)-(1-M79)*100 -> 9.6601942 | P79: =MAX(0,(M79*(IF(N79<0,100/-N79,N79/100)+1)-1)/IF(N79<0,100/-N79,N79/100)) -> 0.10626214
A80: ECU | B80: 7.5 | C80: -105 | D80: -125 | E80: =Win_Probabilities!E81 -> 7.6570945 | F80: =SUMPRODUCT((Win_Probabilities!$F$1:$S$1<>"")*(COLUMN(Win_Probabilities!$F$1:$S$1)-COLUMN(Win_Probabilities!$F$1)>$B80)*Win_Probabilities!$F81:$S81) -> 0.55357447 | G80: =IF(C80<0,-C80/(-C80+100),100/(C80+100)) -> 0.51219512 | H80: =IF(D80<0,-D80/(-D80+100),100/(D80+100)) -> 0.55555556 | I80: =G80+H80-1 -> 0.067750678 | J80: =G80/(G80+H80) -> 0.47969543 | K80: =F80-J80 -> 0.073879039 | L80: =IF(K80>0,"OVER","UNDER") -> OVER | M80: =IF(K80>0,F80,1-F80) -> 0.55357447 | N80: =IF(K80>0,C80,D80) -> -105 | O80: =M80*IF(N80<0,10000/-N80,N80)-(1-M80)*100 -> 8.0788252 | P80: =MAX(0,(M80*(IF(N80<0,100/-N80,N80/100)+1)-1)/IF(N80<0,100/-N80,N80/100)) -> 0.084827664
A81: Army | B81: 7.5 | C81: -145 | D81: 115 | E81: =Win_Probabilities!E82 -> 7.1565272 | F81: =SUMPRODUCT((Win_Probabilities!$F$1:$S$1<>"")*(COLUMN(Win_Probabilities!$F$1:$S$1)-COLUMN(Win_Probabilities!$F$1)>$B81)*Win_Probabilities!$F82:$S82) -> 0.42218234 | G81: =IF(C81<0,-C81/(-C81+100),100/(C81+100)) -> 0.59183673 | H81: =IF(D81<0,-D81/(-D81+100),100/(D81+100)) -> 0.46511628 | I81: =G81+H81-1 -> 0.056953014 | J81: =G81/(G81+H81) -> 0.55994612 | K81: =F81-J81 -> -0.13776377 | L81: =IF(K81>0,"OVER","UNDER") -> UNDER | M81: =IF(K81>0,F81,1-F81) -> 0.57781766 | N81: =IF(K81>0,C81,D81) -> 115 | O81: =M81*IF(N81<0,10000/-N81,N81)-(1-M81)*100 -> 24.230796 | P81: =MAX(0,(M81*(IF(N81<0,100/-N81,N81/100)+1)-1)/IF(N81<0,100/-N81,N81/100)) -> 0.21070257
A82: Boston Coll. | B82: 3.5 | C82: 120 | D82: -155 | E82: =Win_Probabilities!E83 -> 3.8806511 | F82: =SUMPRODUCT((Win_Probabilities!$F$1:$S$1<>"")*(COLUMN(Win_Probabilities!$F$1:$S$1)-COLUMN(Win_Probabilities!$F$1)>$B82)*Win_Probabilities!$F83:$S83) -> 0.59224398 | G82: =IF(C82<0,-C82/(-C82+100),100/(C82+100)) -> 0.45454545 | H82: =IF(D82<0,-D82/(-D82+100),100/(D82+100)) -> 0.60784314 | I82: =G82+H82-1 -> 0.062388592 | J82: =G82/(G82+H82) -> 0.42785235 | K82: =F82-J82 -> 0.16439164 | L82: =IF(K82>0,"OVER","UNDER") -> OVER | M82: =IF(K82>0,F82,1-F82) -> 0.59224398 | N82: =IF(K82>0,C82,D82) -> 120 | O82: =M82*IF(N82<0,10000/-N82,N82)-(1-M82)*100 -> 30.293677 | P82: =MAX(0,(M82*(IF(N82<0,100/-N82,N82/100)+1)-1)/IF(N82<0,100/-N82,N82/100)) -> 0.2524473
A83: Hawaii | B83: 7.5 | C83: 120 | D83: -150 | E83: =Win_Probabilities!E84 -> 7.6694187 | F83: =SUMPRODUCT((Win_Probabilities!$F$1:$S$1<>"")*(COLUMN(Win_Probabilities!$F$1:$S$1)-COLUMN(Win_Probabilities!$F$1)>$B83)*Win_Probabilities!$F84:$S84) -> 0.55267404 | G83: =IF(C83<0,-C83/(-C83+100),100/(C83+100)) -> 0.45454545 | H83: =IF(D83<0,-D83/(-D83+100),100/(D83+100)) -> 0.6 | I83: =G83+H83-1 -> 0.054545455 | J83: =G83/(G83+H83) -> 0.43103448 | K83: =F83-J83 -> 0.12163956 | L83: =IF(K83>0,"OVER","UNDER") -> OVER | M83: =IF(K83>0,F83,1-F83) -> 0.55267404 | N83: =IF(K83>0,C83,D83) -> 120 | O83: =M83*IF(N83<0,10000/-N83,N83)-(1-M83)*100 -> 21.588288 | P83: =MAX(0,(M83*(IF(N83<0,100/-N83,N83/100)+1)-1)/IF(N83<0,100/-N83,N83/100)) -> 0.1799024
A84: Air Force | B84: 7.5 | C84: 125 | D84: -160 | E84: =Win_Probabilities!E85 -> 7.6462592 | F84: =SUMPRODUCT((Win_Probabilities!$F$1:$S$1<>"")*(COLUMN(Win_Probabilities!$F$1:$S$1)-COLUMN(Win_Probabilities!$F$1)>$B84)*Win_Probabilities!$F85:$S85) -> 0.54471709 | G84: =IF(C84<0,-C84/(-C84+100),100/(C84+100)) -> 0.44444444 | H84: =IF(D84<0,-D84/(-D84+100),100/(D84+100)) -> 0.61538462 | I84: =G84+H84-1 -> 0.05982906 | J84: =G84/(G84+H84) -> 0.41935484 | K84: =F84-J84 -> 0.12536226 | L84: =IF(K84>0,"OVER","UNDER") -> OVER | M84: =IF(K84>0,F84,1-F84) -> 0.54471709 | N84: =IF(K84>0,C84,D84) -> 125 | O84: =M84*IF(N84<0,10000/-N84,N84)-(1-M84)*100 -> 22.561346 | P84: =MAX(0,(M84*(IF(N84<0,100/-N84,N84/100)+1)-1)/IF(N84<0,100/-N84,N84/100)) -> 0.18049077
A85: Miami-OH | B85: 7.5 | C85: 110 | D85: -145 | E85: =Win_Probabilities!E86 -> 8.4678167 | F85: =SUMPRODUCT((Win_Probabilities!$F$1:$S$1<>"")*(COLUMN(Win_Probabilities!$F$1:$S$1)-COLUMN(Win_Probabilities!$F$1)>$B85)*Win_Probabilities!$F86:$S86) -> 0.76945139 | G85: =IF(C85<0,-C85/(-C85+100),100/(C85+100)) -> 0.47619048 | H85: =IF(D85<0,-D85/(-D85+100),100/(D85+100)) -> 0.59183673 | I85: =G85+H85-1 -> 0.068027211 | J85: =G85/(G85+H85) -> 0.44585987 | K85: =F85-J85 -> 0.32359151 | L85: =IF(K85>0,"OVER","UNDER") -> OVER | M85: =IF(K85>0,F85,1-F85) -> 0.76945139 | N85: =IF(K85>0,C85,D85) -> 110 | O85: =M85*IF(N85<0,10000/-N85,N85)-(1-M85)*100 -> 61.584791 | P85: =MAX(0,(M85*(IF(N85<0,100/-N85,N85/100)+1)-1)/IF(N85<0,100/-N85,N85/100)) -> 0.55986174
A86: Wash. St. | B86: 4.5 | C86: -166 | D86: 130 | E86: =Win_Probabilities!E87 -> 5.3219415 | F86: =SUMPRODUCT((Win_Probabilities!$F$1:$S$1<>"")*(COLUMN(Win_Probabilities!$F$1:$S$1)-COLUMN(Win_Probabilities!$F$1)>$B86)*Win_Probabilities!$F87:$S87) -> 0.70404422 | G86: =IF(C86<0,-C86/(-C86+100),100/(C86+100)) -> 0.62406015 | H86: =IF(D86<0,-D86/(-D86+100),100/(D86+100)) -> 0.43478261 | I86: =G86+H86-1 -> 0.058842759 | J86: =G86/(G86+H86) -> 0.58937944 | K86: =F86-J86 -> 0.11466478 | L86: =IF(K86>0,"OVER","UNDER") -> OVER | M86: =IF(K86>0,F86,1-F86) -> 0.70404422 | N86: =IF(K86>0,C86,D86) -> -166 | O86: =M86*IF(N86<0,10000/-N86,N86)-(1-M86)*100 -> 12.816724 | P86: =MAX(0,(M86*(IF(N86<0,100/-N86,N86/100)+1)-1)/IF(N86<0,100/-N86,N86/100)) -> 0.21275762
A87: Tulane | B87: 7.5 | C87: 120 | D87: -150 | E87: =Win_Probabilities!E88 -> 6.6425945 | F87: =SUMPRODUCT((Win_Probabilities!$F$1:$S$1<>"")*(COLUMN(Win_Probabilities!$F$1:$S$1)-COLUMN(Win_Probabilities!$F$1)>$B87)*Win_Probabilities!$F88:$S88) -> 0.28695003 | G87: =IF(C87<0,-C87/(-C87+100),100/(C87+100)) -> 0.45454545 | H87: =IF(D87<0,-D87/(-D87+100),100/(D87+100)) -> 0.6 | I87: =G87+H87-1 -> 0.054545455 | J87: =G87/(G87+H87) -> 0.43103448 | K87: =F87-J87 -> -0.14408445 | L87: =IF(K87>0,"OVER","UNDER") -> UNDER | M87: =IF(K87>0,F87,1-F87) -> 0.71304997 | N87: =IF(K87>0,C87,D87) -> -150 | O87: =M87*IF(N87<0,10000/-N87,N87)-(1-M87)*100 -> 18.841661 | P87: =MAX(0,(M87*(IF(N87<0,100/-N87,N87/100)+1)-1)/IF(N87<0,100/-N87,N87/100)) -> 0.28262491
... A138: UMass | B138: 2.5 | C138: -150 | D138: 115 | E138: =Win_Probabilities!E139 -> 3.283195 | F138: =SUMPRODUCT((Win_Probabilities!$F$1:$S$1<>"")*(COLUMN(Win_Probabilities!$F$1:$S$1)-COLUMN(Win_Probabilities!$F$1)>$B138)*Win_Probabilities!$F139:$S139) -> 0.74971869 | G138: =IF(C138<0,-C138/(-C138+100),100/(C138+100)) -> 0.6 | H138: =IF(D138<0,-D138/(-D138+100),100/(D138+100)) -> 0.46511628 | I138: =G138+H138-1 -> 0.065116279 | J138: =G138/(G138+H138) -> 0.56331878 | K138: =F138-J138 -> 0.18639991 | L138: =IF(K138>0,"OVER","UNDER") -> OVER | M138: =IF(K138>0,F138,1-F138) -> 0.74971869 | N138: =IF(K138>0,C138,D138) -> -150 | O138: =M138*IF(N138<0,10000/-N138,N138)-(1-M138)*100 -> 24.953114 | P138: =MAX(0,(M138*(IF(N138<0,100/-N138,N138/100)+1)-1)/IF(N138<0,100/-N138,N138/100)) -> 0.37429671
A140: NDSU has no posted win total (first-year FBS transition) and is excluded.
A141: Lines are BLUE/YELLOW inputs - edit any line or price and every figure recalculates.

Sheet Book_Shop
A1: Per-book OVER lines & prices (VegasInsider, updated Aug 17 2026). UNDER prices are not published on that page, so only OVER bets can be priced here. Blue/yellow cells are inputs.
A2: Team | B2: Model Exp W | C2: BetMGM Line | D2: BetMGM Over | E2: BetMGM ModelP | F2: BetMGM EV/$100 | G2: DraftKings Line | H2: DraftKings Over | I2: DraftKings ModelP | J2: DraftKings EV/$100 | K2: FanDuel Line | L2: FanDuel Over | M2: FanDuel ModelP | N2: FanDuel EV/$100 | O2: RiversCasino Line | P2: RiversCasino Over | Q2: RiversCasino ModelP | R2: RiversCasino EV/$100 | S2: Best Book (Over) | T2: Best EV | U2: Line Spread
A3: Ohio St. | B3: =Win_Probabilities!E2 -> 10.205967 | C3: 9.5 | D3: -175 | E3: =IF(C3="","",SUMPRODUCT((COLUMN(Win_Probabilities!$F$1:$S$1)-COLUMN(Win_Probabilities!$F$1)>C3)*Win_Probabilities!$F2:$S2)) -> 0.74659984 | F3: =E3*IF(D3<0,10000/-D3,D3)-(1-E3)*100 -> 17.322831 | G3: 9.5 | H3: -180 | I3: =IF(G3="","",SUMPRODUCT((COLUMN(Win_Probabilities!$F$1:$S$1)-COLUMN(Win_Probabilities!$F$1)>G3)*Win_Probabilities!$F2:$S2)) -> 0.74659984 | J3: =I3*IF(H3<0,10000/-H3,H3)-(1-I3)*100 -> 16.137752 | K3: 9.5 | L3: -168 | M3: =IF(K3="","",SUMPRODUCT((COLUMN(Win_Probabilities!$F$1:$S$1)-COLUMN(Win_Probabilities!$F$1)>K3)*Win_Probabilities!$F2:$S2)) -> 0.74659984 | N3: =M3*IF(L3<0,10000/-L3,L3)-(1-M3)*100 -> 19.10045 | O3: 9.5 | P3: -195 | Q3: =IF(O3="","",SUMPRODUCT((COLUMN(Win_Probabilities!$F$1:$S$1)-COLUMN(Win_Probabilities!$F$1)>O3)*Win_Probabilities!$F2:$S2)) -> 0.74659984 | R3: =Q3*IF(P3<0,10000/-P3,P3)-(1-Q3)*100 -> 12.947155 | S3: =IF(F3=MAX(F3,J3,N3,R3),"BetMGM",IF(J3=MAX(F3,J3,N3,R3),"DraftKings",IF(N3=MAX(F3,J3,N3,R3),"FanDuel",IF(R3=MAX(F3,J3,N3,R3),"RiversCasino","")))) -> FanDuel | T3: =MAX(F3,J3,N3,R3) -> 19.10045 | U3: =MAX(C3,G3,K3,O3)-MIN(C3,G3,K3,O3) -> 0
A4: Oregon | B4: =Win_Probabilities!E3 -> 10.175094 | C4: 10.5 | D4: 100 | E4: =IF(C4="","",SUMPRODUCT((COLUMN(Win_Probabilities!$F$1:$S$1)-COLUMN(Win_Probabilities!$F$1)>C4)*Win_Probabilities!$F3:$S3)) -> 0.4133802 | F4: =E4*IF(D4<0,10000/-D4,D4)-(1-E4)*100 -> -17.32396 | G4: 10.5 | H4: 100 | I4: =IF(G4="","",SUMPRODUCT((COLUMN(Win_Probabilities!$F$1:$S$1)-COLUMN(Win_Probabilities!$F$1)>G4)*Win_Probabilities!$F3:$S3)) -> 0.4133802 | J4: =I4*IF(H4<0,10000/-H4,H4)-(1-I4)*100 -> -17.32396 | K4: 10.5 | L4: 110 | M4: =IF(K4="","",SUMPRODUCT((COLUMN(Win_Probabilities!$F$1:$S$1)-COLUMN(Win_Probabilities!$F$1)>K4)*Win_Probabilities!$F3:$S3)) -> 0.4133802 | N4: =M4*IF(L4<0,10000/-L4,L4)-(1-M4)*100 -> -13.190158 | O4: 10.5 | P4: 105 | Q4: =IF(O4="","",SUMPRODUCT((COLUMN(Win_Probabilities!$F$1:$S$1)-COLUMN(Win_Probabilities!$F$1)>O4)*Win_Probabilities!$F3:$S3)) -> 0.4133802 | R4: =Q4*IF(P4<0,10000/-P4,P4)-(1-Q4)*100 -> -15.257059 | S4: =IF(F4=MAX(F4,J4,N4,R4),"BetMGM",IF(J4=MAX(F4,J4,N4,R4),"DraftKings",IF(N4=MAX(F4,J4,N4,R4),"FanDuel",IF(R4=MAX(F4,J4,N4,R4),"RiversCasino","")))) -> FanDuel | T4: =MAX(F4,J4,N4,R4) -> -13.190158 | U4: =MAX(C4,G4,K4,O4)-MIN(C4,G4,K4,O4) -> 0
A5: Notre Dame | B5: =Win_Probabilities!E4 -> 10.800983 | C5: 11.5 | D5: 150 | E5: =IF(C5="","",SUMPRODUCT((COLUMN(Win_Probabilities!$F$1:$S$1)-COLUMN(Win_Probabilities!$F$1)>C5)*Win_Probabilities!$F4:$S4)) -> 0.26006172 | F5: =E5*IF(D5<0,10000/-D5,D5)-(1-E5)*100 -> -34.98457 | G5: 11.5 | H5: 160 | I5: =IF(G5="","",SUMPRODUCT((COLUMN(Win_Probabilities!$F$1:$S$1)-COLUMN(Win_Probabilities!$F$1)>G5)*Win_Probabilities!$F4:$S4)) -> 0.26006172 | J5: =I5*IF(H5<0,10000/-H5,H5)-(1-I5)*100 -> -32.383953 | K5: 11.5 | L5: 164 | M5: =IF(K5="","",SUMPRODUCT((COLUMN(Win_Probabilities!$F$1:$S$1)-COLUMN(Win_Probabilities!$F$1)>K5)*Win_Probabilities!$F4:$S4)) -> 0.26006172 | N5: =M5*IF(L5<0,10000/-L5,L5)-(1-M5)*100 -> -31.343706 | O5: 11.5 | P5: 155 | Q5: =IF(O5="","",SUMPRODUCT((COLUMN(Win_Probabilities!$F$1:$S$1)-COLUMN(Win_Probabilities!$F$1)>O5)*Win_Probabilities!$F4:$S4)) -> 0.26006172 | R5: =Q5*IF(P5<0,10000/-P5,P5)-(1-Q5)*100 -> -33.684261 | S5: =IF(F5=MAX(F5,J5,N5,R5),"BetMGM",IF(J5=MAX(F5,J5,N5,R5),"DraftKings",IF(N5=MAX(F5,J5,N5,R5),"FanDuel",IF(R5=MAX(F5,J5,N5,R5),"RiversCasino","")))) -> FanDuel | T5: =MAX(F5,J5,N5,R5) -> -31.343706 | U5: =MAX(C5,G5,K5,O5)-MIN(C5,G5,K5,O5) -> 0
A6: Georgia | B6: =Win_Probabilities!E5 -> 9.9177097 | C6: 10.5 | D6: 140 | E6: =IF(C6="","",SUMPRODUCT((COLUMN(Win_Probabilities!$F$1:$S$1)-COLUMN(Win_Probabilities!$F$1)>C6)*Win_Probabilities!$F5:$S5)) -> 0.34533242 | F6: =E6*IF(D6<0,10000/-D6,D6)-(1-E6)*100 -> -17.12022 | G6: 9.5 | H6: -190 | I6: =IF(G6="","",SUMPRODUCT((COLUMN(Win_Probabilities!$F$1:$S$1)-COLUMN(Win_Probabilities!$F$1)>G6)*Win_Probabilities!$F5:$S5)) -> 0.65380909 | J6: =I6*IF(H6<0,10000/-H6,H6)-(1-I6)*100 -> -0.20808638 | K6: 10.5 | L6: 138 | M6: =IF(K6="","",SUMPRODUCT((COLUMN(Win_Probabilities!$F$1:$S$1)-COLUMN(Win_Probabilities!$F$1)>K6)*Win_Probabilities!$F5:$S5)) -> 0.34533242 | N6: =M6*IF(L6<0,10000/-L6,L6)-(1-M6)*100 -> -17.810885 | O6: 9.5 | P6: -200 | Q6: =IF(O6="","",SUMPRODUCT((COLUMN(Win_Probabilities!$F$1:$S$1)-COLUMN(Win_Probabilities!$F$1)>O6)*Win_Probabilities!$F5:$S5)) -> 0.65380909 | R6: =Q6*IF(P6<0,10000/-P6,P6)-(1-Q6)*100 -> -1.9286366 | S6: =IF(F6=MAX(F6,J6,N6,R6),"BetMGM",IF(J6=MAX(F6,J6,N6,R6),"DraftKings",IF(N6=MAX(F6,J6,N6,R6),"FanDuel",IF(R6=MAX(F6,J6,N6,R6),"RiversCasino","")))) -> DraftKings | T6: =MAX(F6,J6,N6,R6) -> -0.20808638 | U6: =MAX(C6,G6,K6,O6)-MIN(C6,G6,K6,O6) -> 1
